<?xml version="1.0" encoding="utf-8"?>
<!-- This URDF was automatically created by SolidWorks to URDF Exporter! Originally created by Stephen Brawner (brawner@gmail.com) 
     Commit Version: 1.5.1-0-g916b5db  Build Version: 1.5.7152.31018
     For more information, please see http://wiki.ros.org/sw_urdf_exporter -->
<robot
  name="car.SLDASM">
  <link
    name="base_link">
    <inertial>
      <origin
        xyz="0.00179285805377807 -9.17629428176305E-06 0.0360041827944672"
        rpy="0 0 0" />
      <mass
        value="0.602602841617535" />
      <inertia
        ixx="0.000249611268649524"
        ixy="9.06360029792656E-08"
        ixz="9.87057318330381E-07"
        iyy="0.000333256060598711"
        iyz="-6.76297915903039E-10"
        izz="0.000511455341525986" />
    </inertial>
    <visual>
      <origin
        xyz="0 0 0"
        rpy="0 0 0" />
      <geometry>
        <mesh
          filename="package://car.SLDASM/meshes/base_link.STL" />
      </geometry>
      <material
        name="">
        <color
          rgba="0.337254901960784 0.549019607843137 0.282352941176471 1" />
      </material>
    </visual>
    <collision>
      <origin
        xyz="0 0 0"
        rpy="0 0 0" />
      <geometry>
        <mesh
          filename="package://car.SLDASM/meshes/base_link.STL" />
      </geometry>
    </collision>
  </link>
  <link
    name="lb_wheel">
    <inertial>
      <origin
        xyz="7.45521179512654E-11 -0.004974430648039 2.15639311962335E-12"
        rpy="0 0 0" />
      <mass
        value="0.0165512934644656" />
      <inertia
        ixx="5.54537335913689E-06"
        ixy="4.45030561211828E-14"
        ixz="-1.86644533759541E-15"
        iyy="1.0900553011918E-05"
        iyz="8.14435618791268E-15"
        izz="5.54537337589587E-06" />
    </inertial>
    <visual>
      <origin
        xyz="0 0 0"
        rpy="0 0 0" />
      <geometry>
        <mesh
          filename="package://car.SLDASM/meshes/lb_wheel.STL" />
      </geometry>
      <material
        name="">
        <color
          rgba="0.647058823529412 0.858823529411765 0.905882352941176 1" />
      </material>
    </visual>
    <collision>
      <origin
        xyz="0 0 0"
        rpy="0 0 0" />
      <geometry>
        <mesh
          filename="package://car.SLDASM/meshes/lb_wheel.STL" />
      </geometry>
    </collision>
  </link>
  <joint
    name="lb_wheel"
    type="continuous">
    <origin
      xyz="-0.0645823070261228 0.075 0.0195"
      rpy="0 0 0" />
    <parent
      link="base_link" />
    <child
      link="lb_wheel" />
    <axis
      xyz="0 1 0" />
    <limit
      lower="-120"
      upper="120"
      effort="50"
      velocity="20" />
    <safety_controller
      soft_upper="100"
      soft_lower="40"
      k_velocity="60" />
  </joint>
  <link
    name="rb_wheel">
    <inertial>
      <origin
        xyz="7.45521179512654E-11 0.004974430648039 -2.15638271128249E-12"
        rpy="0 0 0" />
      <mass
        value="0.0165512934644656" />
      <inertia
        ixx="5.54537335913689E-06"
        ixy="-4.45030610158691E-14"
        ixz="1.86644570723039E-15"
        iyy="1.0900553011918E-05"
        iyz="8.14435599503619E-15"
        izz="5.54537337589587E-06" />
    </inertial>
    <visual>
      <origin
        xyz="0 0 0"
        rpy="0 0 0" />
      <geometry>
        <mesh
          filename="package://car.SLDASM/meshes/rb_wheel.STL" />
      </geometry>
      <material
        name="">
        <color
          rgba="0.647058823529412 0.858823529411765 0.905882352941176 1" />
      </material>
    </visual>
    <collision>
      <origin
        xyz="0 0 0"
        rpy="0 0 0" />
      <geometry>
        <mesh
          filename="package://car.SLDASM/meshes/rb_wheel.STL" />
      </geometry>
    </collision>
  </link>
  <joint
    name="rb_wheel"
    type="continuous">
    <origin
      xyz="-0.0645823070261227 -0.075 0.0195"
      rpy="0 0 0" />
    <parent
      link="base_link" />
    <child
      link="rb_wheel" />
    <axis
      xyz="0 -1 0" />
    <limit
      lower="-120"
      upper="120"
      effort="50"
      velocity="20" />
    <safety_controller
      soft_upper="100"
      soft_lower="40"
      k_velocity="60" />
  </joint>
  <link
    name="servo">
    <inertial>
      <origin
        xyz="-0.000670564663515699 -0.000838904673663491 0.00577004498133679"
        rpy="0 0 0" />
      <mass
        value="0.00102812398052869" />
      <inertia
        ixx="5.06965999363832E-08"
        ixy="3.59582150864825E-10"
        ixz="-2.47323116704478E-09"
        iyy="4.13995778738808E-08"
        iyz="3.89727361496621E-09"
        izz="1.51604797111521E-08" />
    </inertial>
    <visual>
      <origin
        xyz="0 0 0"
        rpy="0 0 0" />
      <geometry>
        <mesh
          filename="package://car.SLDASM/meshes/servo.STL" />
      </geometry>
      <material
        name="">
        <color
          rgba="0.67843137254902 0.176470588235294 0.725490196078431 1" />
      </material>
    </visual>
    <collision>
      <origin
        xyz="0 0 0"
        rpy="0 0 0" />
      <geometry>
        <mesh
          filename="package://car.SLDASM/meshes/servo.STL" />
      </geometry>
    </collision>
  </link>
  <joint
    name="servo"
    type="revolute">
    <origin
      xyz="0.0854176929738543 -0.00999999999994559 0.0149999999999222"
      rpy="0 0 0" />
    <parent
      link="base_link" />
    <child
      link="servo" />
    <axis
      xyz="1 0 0" />
    <limit
      lower="-90"
      upper="90"
      effort="0"
      velocity="0" />
  </joint>
  <link
    name="turn_l">
    <inertial>
      <origin
        xyz="0.0063864243623073 0.003713246739234 4.67852918480532E-05"
        rpy="0 0 0" />
      <mass
        value="0.00262306791605392" />
      <inertia
        ixx="1.02648987046787E-07"
        ixy="6.52855074516281E-08"
        ixz="7.03843776370824E-14"
        iyy="2.32734584765491E-07"
        iyz="-7.50458574116369E-14"
        izz="2.55841528338023E-07" />
    </inertial>
    <visual>
      <origin
        xyz="0 0 0"
        rpy="0 0 0" />
      <geometry>
        <mesh
          filename="package://car.SLDASM/meshes/turn_l.STL" />
      </geometry>
      <material
        name="">
        <color
          rgba="0.63921568627451 0.772549019607843 0.741176470588235 1" />
      </material>
    </visual>
    <collision>
      <origin
        xyz="0 0 0"
        rpy="0 0 0" />
      <geometry>
        <mesh
          filename="package://car.SLDASM/meshes/turn_l.STL" />
      </geometry>
    </collision>
  </link>
  <joint
    name="turn_l"
    type="revolute">
    <origin
      xyz="0.0754177109675237 0.0490967647728443 0.012000024229292"
      rpy="0 0 0" />
    <parent
      link="base_link" />
    <child
      link="turn_l" />
    <axis
      xyz="0 0 -1" />
    <limit
      lower="-45"
      upper="45"
      effort="0"
      velocity="0" />
  </joint>
  <link
    name="lf_wheel">
    <inertial>
      <origin
        xyz="-9.50528544763074E-12 -0.00497443064818028 7.28544672506937E-11"
        rpy="0 0 0" />
      <mass
        value="0.0165512934642293" />
      <inertia
        ixx="5.54537337603311E-06"
        ixy="6.43034739607792E-15"
        ixz="-8.45382228219338E-17"
        iyy="1.09005530118524E-05"
        iyz="4.24854590134975E-14"
        izz="5.54537335893534E-06" />
    </inertial>
    <visual>
      <origin
        xyz="0 0 0"
        rpy="0 0 0" />
      <geometry>
        <mesh
          filename="package://car.SLDASM/meshes/lf_wheel.STL" />
      </geometry>
      <material
        name="">
        <color
          rgba="0.647058823529412 0.858823529411765 0.905882352941176 1" />
      </material>
    </visual>
    <collision>
      <origin
        xyz="0 0 0"
        rpy="0 0 0" />
      <geometry>
        <mesh
          filename="package://car.SLDASM/meshes/lf_wheel.STL" />
      </geometry>
    </collision>
  </link>
  <joint
    name="lf_wheel"
    type="continuous">
    <origin
      xyz="0 0.0259032352271557 0"
      rpy="0 0 0" />
    <parent
      link="turn_l" />
    <child
      link="lf_wheel" />
    <axis
      xyz="0 1 0" />
    <limit
      lower="-120"
      upper="120"
      effort="0"
      velocity="20" />
  </joint>
  <link
    name="link_l">
    <inertial>
      <origin
        xyz="-0.0909323159422917 -0.0450129080904538 0.0297944618792993"
        rpy="0 0 0" />
      <mass
        value="0.861863465978921" />
      <inertia
        ixx="0.00123973903447922"
        ixy="6.30053169404082E-07"
        ixz="-2.77053556965517E-05"
        iyy="0.00235825932701772"
        iyz="-1.89249544963806E-07"
        izz="0.00272890063157574" />
    </inertial>
    <visual>
      <origin
        xyz="0 0 0"
        rpy="0 0 0" />
      <geometry>
        <mesh
          filename="package://car.SLDASM/meshes/link_l.STL" />
      </geometry>
      <material
        name="">
        <color
          rgba="0.301960784313725 0.145098039215686 0.298039215686275 1" />
      </material>
    </visual>
    <collision>
      <origin
        xyz="0 0 0"
        rpy="0 0 0" />
      <geometry>
        <mesh
          filename="package://car.SLDASM/meshes/link_l.STL" />
      </geometry>
    </collision>
  </link>
  <joint
    name="link_l"
    type="revolute">
    <origin
      xyz="0.0299999803666197 -0.00409676459519989 -0.00508581828436026"
      rpy="0 0 0" />
    <parent
      link="turn_l" />
    <child
      link="link_l" />
    <axis
      xyz="0 0 1" />
    <limit
      lower="0"
      upper="0"
      effort="0"
      velocity="0" />
  </joint>
  <link
    name="link_ll">
    <inertial>
      <origin
        xyz="-0.0859323160512497 -0.0450129072987975 0.0186228737691628"
        rpy="0 0 0" />
      <mass
        value="0.861863465978921" />
      <inertia
        ixx="0.00123973903447922"
        ixy="6.30053169404027E-07"
        ixz="-2.77053556965516E-05"
        iyy="0.00235825932701772"
        iyz="-1.89249544963836E-07"
        izz="0.00272890063157574" />
    </inertial>
    <visual>
      <origin
        xyz="0 0 0"
        rpy="0 0 0" />
      <geometry>
        <mesh
          filename="package://car.SLDASM/meshes/link_ll.STL" />
      </geometry>
      <material
        name="">
        <color
          rgba="0.47843137254902 0.627450980392157 0.141176470588235 1" />
      </material>
    </visual>
    <collision>
      <origin
        xyz="0 0 0"
        rpy="0 0 0" />
      <geometry>
        <mesh
          filename="package://car.SLDASM/meshes/link_ll.STL" />
      </geometry>
    </collision>
  </link>
  <joint
    name="link_ll"
    type="revolute">
    <origin
      xyz="0.0249999804755777 -0.00409676538685611 0.00608576982577623"
      rpy="0 0 0" />
    <parent
      link="turn_l" />
    <child
      link="link_ll" />
    <axis
      xyz="0 0 -1" />
    <limit
      lower="0"
      upper="0"
      effort="0"
      velocity="0" />
  </joint>
  <link
    name="turn_r">
    <inertial>
      <origin
        xyz="0.00547231101220577 -0.00409679706510864 -0.00022824773399128"
        rpy="0 0 0" />
      <mass
        value="0.00250027899801977" />
      <inertia
        ixx="1.02054358011643E-07"
        ixy="-6.52855088977075E-08"
        ixz="-7.04722957241176E-14"
        iyy="2.32139951918833E-07"
        iyz="-7.50928903784836E-14"
        izz="2.55429486721656E-07" />
    </inertial>
    <visual>
      <origin
        xyz="0 0 0"
        rpy="0 0 0" />
      <geometry>
        <mesh
          filename="package://car.SLDASM/meshes/turn_r.STL" />
      </geometry>
      <material
        name="">
        <color
          rgba="0.63921568627451 0.772549019607843 0.741176470588235 1" />
      </material>
    </visual>
    <collision>
      <origin
        xyz="0 0 0"
        rpy="0 0 0" />
      <geometry>
        <mesh
          filename="package://car.SLDASM/meshes/turn_r.STL" />
      </geometry>
    </collision>
  </link>
  <joint
    name="turn_r"
    type="revolute">
    <origin
      xyz="0.0754177109675115 -0.0490967647728332 0.01199997577068"
      rpy="0 0 0" />
    <parent
      link="base_link" />
    <child
      link="turn_r" />
    <axis
      xyz="0 0 1" />
    <limit
      lower="-45"
      upper="45"
      effort="0"
      velocity="0" />
  </joint>
  <link
    name="rf_wheel">
    <inertial>
      <origin
        xyz="-9.50342582406449E-12 0.00497443064818727 -7.28546997036394E-11"
        rpy="0 0 0" />
      <mass
        value="0.0165512934642293" />
      <inertia
        ixx="5.54537337603312E-06"
        ixy="-6.43030017625828E-15"
        ixz="8.4532800324454E-17"
        iyy="1.09005530118525E-05"
        iyz="4.24854559078279E-14"
        izz="5.54537335893534E-06" />
    </inertial>
    <visual>
      <origin
        xyz="0 0 0"
        rpy="0 0 0" />
      <geometry>
        <mesh
          filename="package://car.SLDASM/meshes/rf_wheel.STL" />
      </geometry>
      <material
        name="">
        <color
          rgba="0.647058823529412 0.858823529411765 0.905882352941176 1" />
      </material>
    </visual>
    <collision>
      <origin
        xyz="0 0 0"
        rpy="0 0 0" />
      <geometry>
        <mesh
          filename="package://car.SLDASM/meshes/rf_wheel.STL" />
      </geometry>
    </collision>
  </link>
  <joint
    name="rf_wheel"
    type="continuous">
    <origin
      xyz="0 -0.0259032352271723 0"
      rpy="0 0 0" />
    <parent
      link="turn_r" />
    <child
      link="rf_wheel" />
    <axis
      xyz="0 -1 0" />
    <limit
      lower="-120"
      upper="120"
      effort="0"
      velocity="20" />
  </joint>
  <link
    name="link_rr">
    <inertial>
      <origin
        xyz="-0.0783613437139762 0.0125768768467714 0.00389594723193967"
        rpy="0 0 0" />
      <mass
        value="0.861863465978921" />
      <inertia
        ixx="0.00123973903447922"
        ixy="6.30053169404052E-07"
        ixz="-2.77053556965516E-05"
        iyy="0.00235825932701772"
        iyz="-1.89249544963833E-07"
        izz="0.00272890063157574" />
    </inertial>
    <visual>
      <origin
        xyz="0 0 0"
        rpy="0 0 0" />
      <geometry>
        <mesh
          filename="package://car.SLDASM/meshes/link_rr.STL" />
      </geometry>
      <material
        name="">
        <color
          rgba="0.301960784313725 0.145098039215686 0.298039215686275 1" />
      </material>
    </visual>
    <collision>
      <origin
        xyz="0 0 0"
        rpy="0 0 0" />
      <geometry>
        <mesh
          filename="package://car.SLDASM/meshes/link_rr.STL" />
      </geometry>
    </collision>
  </link>
  <joint
    name="link_rr"
    type="revolute">
    <origin
      xyz="0.0174290081383163 0.0365069800132524 0.0208127448216114"
      rpy="0 0 0" />
    <parent
      link="turn_r" />
    <child
      link="link_rr" />
    <axis
      xyz="-1 0 0" />
    <limit
      lower="0"
      upper="0"
      effort="0"
      velocity="0" />
  </joint>
  <link
    name="camera">
    <inertial>
      <origin
        xyz="-0.0135786496601567 1.28905432960386E-07 0.00611034086129218"
        rpy="0 0 0" />
      <mass
        value="0.186904128800083" />
      <inertia
        ixx="0.000133784122207917"
        ixy="9.95919502464347E-11"
        ixz="2.02433719255545E-07"
        iyy="1.0664060130472E-05"
        iyz="3.36230004794001E-10"
        izz="0.000138831068112444" />
    </inertial>
    <visual>
      <origin
        xyz="0 0 0"
        rpy="0 0 0" />
      <geometry>
        <mesh
          filename="package://car.SLDASM/meshes/camera.STL" />
      </geometry>
      <material
        name="">
        <color
          rgba="0.792156862745098 0.819607843137255 0.933333333333333 1" />
      </material>
    </visual>
    <collision>
      <origin
        xyz="0 0 0"
        rpy="0 0 0" />
      <geometry>
        <mesh
          filename="package://car.SLDASM/meshes/camera.STL" />
      </geometry>
    </collision>
  </link>
  <joint
    name="camera"
    type="revolute">
    <origin
      xyz="0.0699787259278233 0 0.041061032953946"
      rpy="0 0 0" />
    <parent
      link="base_link" />
    <child
      link="camera" />
    <axis
      xyz="0 -1 0" />
    <limit
      lower="-60"
      upper="60"
      effort="0"
      velocity="0" />
  </joint>
</robot>